<robot name = "robot">
    <link name="parent">
        <inertial>
            <origin xyz="2 2 1.5" rpy="0 0 0"/>
            <mass value="1" />
            <inertia ixx="100" ixy="0" ixz="0" iyy="100" iyz="0" izz="100" />
        </inertial>
        <visual>
            <origin xyz="2 2 1.5" rpy="0 0 0"/>
            <geometry>
                <box size="1 1 1" />
            </geometry>
            <material name="Cyan">
                <color rgba="0 1.0 1.0 1.0"/>
            </material>
        </visual>
        <collision>
            <origin xyz="2 2 1.5" rpy="0 0 0"/>
            <geometry>
                <box size="1 1 1" />
            </geometry>
        </collision>
    </link>
    <joint name="parent_child2" type="revolute">
       <parent link="parent"/>
       <child  link="child2"/>
       <origin rpy="0 0 0" xyz="1.5 1.2 1.0" />
       <axis xyz="0 1 0"/>
       <limit effort="0.0" lower="-3.14159" upper="3.14159" velocity="0.0"/>
    </joint>
    <link name="child2">
        <inertial>
            <origin xyz="-0.6 0.4 0.1" rpy="0 0 0"/>
            <mass value="1" />
            <inertia ixx="100" ixy="0" ixz="0" iyy="100" iyz="0" izz="100" />
        </inertial>
        <visual>
            <origin xyz="-0.6 0.4 0.1" rpy="0 0 0"/>
            <geometry>
                <box size="1.2 0.2 0.2" />
            </geometry>
            <material name="Cyan">
                <color rgba="0 1.0 1.0 1.0"/>
            </material>
        </visual>
        <collision>
            <origin xyz="-0.6 0.4 0.1" rpy="0 0 0"/>
            <geometry>
                <box size="1.2 0.2 0.2" />
            </geometry>
        </collision>
    </link>
    <joint name="parent_child1" type="revolute">
       <parent link="parent"/>
       <child  link="child1"/>
       <origin rpy="0 0 0" xyz="2.5 1.4 1.0" />
       <axis xyz="0 1 0"/>
       <limit effort="0.0" lower="-3.14159" upper="3.14159" velocity="0.0"/>
    </joint>
    <link name="child1">
        <inertial>
            <origin xyz="0.6 0.4 0.1" rpy="0 0 0"/>
            <mass value="1" />
            <inertia ixx="100" ixy="0" ixz="0" iyy="100" iyz="0" izz="100" />
        </inertial>
        <visual>
            <origin xyz="0.6 0.4 0.1" rpy="0 0 0"/>
            <geometry>
                <box size="1.2 0.2 0.2" />
            </geometry>
            <material name="Cyan">
                <color rgba="0 1.0 1.0 1.0"/>
            </material>
        </visual>
        <collision>
            <origin xyz="0.6 0.4 0.1" rpy="0 0 0"/>
            <geometry>
                <box size="1.2 0.2 0.2" />
            </geometry>
        </collision>
    </link>
</robot>